[2025-06-19T08:42:49.148+0000] {local_task_job_runner.py:120} INFO - ::group::Pre task execution logs
[2025-06-19T08:42:49.174+0000] {taskinstance.py:2076} INFO - Dependencies all met for dep_context=non-requeueable deps ti=<TaskInstance: kse100_forecasting.train_lasso manual__2025-06-19T08:42:26.783185+00:00 [queued]>
[2025-06-19T08:42:49.182+0000] {taskinstance.py:2076} INFO - Dependencies all met for dep_context=requeueable deps ti=<TaskInstance: kse100_forecasting.train_lasso manual__2025-06-19T08:42:26.783185+00:00 [queued]>
[2025-06-19T08:42:49.183+0000] {taskinstance.py:2306} INFO - Starting attempt 1 of 3
[2025-06-19T08:42:49.198+0000] {taskinstance.py:2330} INFO - Executing <Task(PythonOperator): train_lasso> on 2025-06-19 08:42:26.783185+00:00
[2025-06-19T08:42:49.204+0000] {standard_task_runner.py:63} INFO - Started process 498 to run task
[2025-06-19T08:42:49.207+0000] {standard_task_runner.py:90} INFO - Running: ['***', 'tasks', 'run', 'kse100_forecasting', 'train_lasso', 'manual__2025-06-19T08:42:26.783185+00:00', '--job-id', '1057', '--raw', '--subdir', 'DAGS_FOLDER/kse100_forecasting_dag.py', '--cfg-path', '/tmp/tmp1lda3rn8']
[2025-06-19T08:42:49.209+0000] {standard_task_runner.py:91} INFO - Job 1057: Subtask train_lasso
[2025-06-19T08:42:49.250+0000] {task_command.py:426} INFO - Running <TaskInstance: kse100_forecasting.train_lasso manual__2025-06-19T08:42:26.783185+00:00 [running]> on host 57c57e92cb28
[2025-06-19T08:42:49.364+0000] {taskinstance.py:2648} INFO - Exporting env vars: AIRFLOW_CTX_DAG_OWNER='***' AIRFLOW_CTX_DAG_ID='kse100_forecasting' AIRFLOW_CTX_TASK_ID='train_lasso' AIRFLOW_CTX_EXECUTION_DATE='2025-06-19T08:42:26.783185+00:00' AIRFLOW_CTX_TRY_NUMBER='1' AIRFLOW_CTX_DAG_RUN_ID='manual__2025-06-19T08:42:26.783185+00:00'
[2025-06-19T08:42:49.365+0000] {taskinstance.py:430} INFO - ::endgroup::
[2025-06-19T08:42:49.570+0000] {logging_mixin.py:188} INFO - Lasso: R2=0.7022, MSE=7513328.6221, MAE=2109.6095
[2025-06-19T08:42:49.576+0000] {logging_mixin.py:188} INFO - Error predicting on full dataset (Lasso): [Errno 2] No such file or directory: '/opt/***/data/transformed_data.csv'
[2025-06-19T08:42:49.576+0000] {python.py:237} INFO - Done. Returned value was: ('/opt/***/dataKse/models/kse_lasso_model.pkl', '/opt/***/dataKse/models/kse_lasso_metrics.csv')
[2025-06-19T08:42:49.577+0000] {taskinstance.py:441} INFO - ::group::Post task execution logs
[2025-06-19T08:42:49.594+0000] {taskinstance.py:1206} INFO - Marking task as SUCCESS. dag_id=kse100_forecasting, task_id=train_lasso, run_id=manual__2025-06-19T08:42:26.783185+00:00, execution_date=20250619T084226, start_date=20250619T084249, end_date=20250619T084249
[2025-06-19T08:42:49.619+0000] {local_task_job_runner.py:240} INFO - Task exited with return code 0
[2025-06-19T08:42:49.634+0000] {taskinstance.py:3498} INFO - 0 downstream tasks scheduled from follow-on schedule check
[2025-06-19T08:42:49.636+0000] {local_task_job_runner.py:222} INFO - ::endgroup::
