[2025-06-18T10:47:13.780+0000] {local_task_job_runner.py:120} INFO - ::group::Pre task execution logs
[2025-06-18T10:47:13.811+0000] {taskinstance.py:2076} INFO - Dependencies all met for dep_context=non-requeueable deps ti=<TaskInstance: usdpkr_forecasting_modular.train_lasso manual__2025-06-14T17:26:10.292123+00:00 [queued]>
[2025-06-18T10:47:13.822+0000] {taskinstance.py:2076} INFO - Dependencies all met for dep_context=requeueable deps ti=<TaskInstance: usdpkr_forecasting_modular.train_lasso manual__2025-06-14T17:26:10.292123+00:00 [queued]>
[2025-06-18T10:47:13.823+0000] {taskinstance.py:2306} INFO - Starting attempt 3 of 3
[2025-06-18T10:47:13.839+0000] {taskinstance.py:2330} INFO - Executing <Task(PythonOperator): train_lasso> on 2025-06-14 17:26:10.292123+00:00
[2025-06-18T10:47:13.846+0000] {standard_task_runner.py:63} INFO - Started process 865 to run task
[2025-06-18T10:47:13.849+0000] {standard_task_runner.py:90} INFO - Running: ['***', 'tasks', 'run', 'usdpkr_forecasting_modular', 'train_lasso', 'manual__2025-06-14T17:26:10.292123+00:00', '--job-id', '540', '--raw', '--subdir', 'DAGS_FOLDER/usdpkr_forecasting_dag.py', '--cfg-path', '/tmp/tmp08mv22q6']
[2025-06-18T10:47:13.852+0000] {standard_task_runner.py:91} INFO - Job 540: Subtask train_lasso
[2025-06-18T10:47:13.897+0000] {task_command.py:426} INFO - Running <TaskInstance: usdpkr_forecasting_modular.train_lasso manual__2025-06-14T17:26:10.292123+00:00 [running]> on host 9c4806d77c92
[2025-06-18T10:47:14.017+0000] {taskinstance.py:2648} INFO - Exporting env vars: AIRFLOW_CTX_DAG_OWNER='***' AIRFLOW_CTX_DAG_ID='usdpkr_forecasting_modular' AIRFLOW_CTX_TASK_ID='train_lasso' AIRFLOW_CTX_EXECUTION_DATE='2025-06-14T17:26:10.292123+00:00' AIRFLOW_CTX_TRY_NUMBER='3' AIRFLOW_CTX_DAG_RUN_ID='manual__2025-06-14T17:26:10.292123+00:00'
[2025-06-18T10:47:14.019+0000] {taskinstance.py:430} INFO - ::endgroup::
[2025-06-18T10:47:14.060+0000] {model_steps.py:815} ERROR - Error in train_lasso_model: Found array with 0 sample(s) (shape=(0, 45)) while a minimum of 1 is required by LassoCV.
[2025-06-18T10:47:14.061+0000] {taskinstance.py:441} INFO - ::group::Post task execution logs
[2025-06-18T10:47:14.061+0000] {taskinstance.py:2905} ERROR - Task failed with exception
Traceback (most recent call last):
  File "/home/airflow/.local/lib/python3.12/site-packages/airflow/models/taskinstance.py", line 465, in _execute_task
    result = _execute_callable(context=context, **execute_callable_kwargs)
             ^^^^^^^^^^^^^^^^^^^^^^^^^^^^^^^^^^^^^^^^^^^^^^^^^^^^^^^^^^^^^
  File "/home/airflow/.local/lib/python3.12/site-packages/airflow/models/taskinstance.py", line 432, in _execute_callable
    return execute_callable(context=context, **execute_callable_kwargs)
           ^^^^^^^^^^^^^^^^^^^^^^^^^^^^^^^^^^^^^^^^^^^^^^^^^^^^^^^^^^^^
  File "/home/airflow/.local/lib/python3.12/site-packages/airflow/models/baseoperator.py", line 400, in wrapper
    return func(self, *args, **kwargs)
           ^^^^^^^^^^^^^^^^^^^^^^^^^^^
  File "/home/airflow/.local/lib/python3.12/site-packages/airflow/operators/python.py", line 235, in execute
    return_value = self.execute_callable()
                   ^^^^^^^^^^^^^^^^^^^^^^^
  File "/home/airflow/.local/lib/python3.12/site-packages/airflow/operators/python.py", line 252, in execute_callable
    return self.python_callable(*self.op_args, **self.op_kwargs)
           ^^^^^^^^^^^^^^^^^^^^^^^^^^^^^^^^^^^^^^^^^^^^^^^^^^^^^
  File "/opt/airflow/dags/inflation_modules/model_steps.py", line 806, in train_lasso_model
    model.fit(X_train, y_train)
  File "/home/airflow/.local/lib/python3.12/site-packages/sklearn/linear_model/_coordinate_descent.py", line 2182, in fit
    return super().fit(X, y, sample_weight=sample_weight, **params)
           ^^^^^^^^^^^^^^^^^^^^^^^^^^^^^^^^^^^^^^^^^^^^^^^^^^^^^^^^
  File "/home/airflow/.local/lib/python3.12/site-packages/sklearn/base.py", line 1363, in wrapper
    return fit_method(estimator, *args, **kwargs)
           ^^^^^^^^^^^^^^^^^^^^^^^^^^^^^^^^^^^^^^
  File "/home/airflow/.local/lib/python3.12/site-packages/sklearn/linear_model/_coordinate_descent.py", line 1693, in fit
    X, y = validate_data(
           ^^^^^^^^^^^^^^
  File "/home/airflow/.local/lib/python3.12/site-packages/sklearn/utils/validation.py", line 2966, in validate_data
    X = check_array(X, input_name="X", **check_X_params)
        ^^^^^^^^^^^^^^^^^^^^^^^^^^^^^^^^^^^^^^^^^^^^^^^^
  File "/home/airflow/.local/lib/python3.12/site-packages/sklearn/utils/validation.py", line 1128, in check_array
    raise ValueError(
ValueError: Found array with 0 sample(s) (shape=(0, 45)) while a minimum of 1 is required by LassoCV.
[2025-06-18T10:47:14.078+0000] {taskinstance.py:1206} INFO - Marking task as FAILED. dag_id=usdpkr_forecasting_modular, task_id=train_lasso, run_id=manual__2025-06-14T17:26:10.292123+00:00, execution_date=20250614T172610, start_date=20250618T104713, end_date=20250618T104714
[2025-06-18T10:47:14.090+0000] {standard_task_runner.py:110} ERROR - Failed to execute job 540 for task train_lasso (Found array with 0 sample(s) (shape=(0, 45)) while a minimum of 1 is required by LassoCV.; 865)
[2025-06-18T10:47:14.103+0000] {local_task_job_runner.py:240} INFO - Task exited with return code 1
[2025-06-18T10:47:14.126+0000] {taskinstance.py:3498} INFO - 0 downstream tasks scheduled from follow-on schedule check
[2025-06-18T10:47:14.131+0000] {local_task_job_runner.py:222} INFO - ::endgroup::
