[2025-06-18T19:00:16.135+0000] {local_task_job_runner.py:120} INFO - ::group::Pre task execution logs
[2025-06-18T19:00:16.167+0000] {taskinstance.py:2076} INFO - Dependencies all met for dep_context=non-requeueable deps ti=<TaskInstance: kse100_forecasting.train_lasso manual__2025-06-18T18:59:49.630931+00:00 [queued]>
[2025-06-18T19:00:16.180+0000] {taskinstance.py:2076} INFO - Dependencies all met for dep_context=requeueable deps ti=<TaskInstance: kse100_forecasting.train_lasso manual__2025-06-18T18:59:49.630931+00:00 [queued]>
[2025-06-18T19:00:16.183+0000] {taskinstance.py:2306} INFO - Starting attempt 1 of 3
[2025-06-18T19:00:16.223+0000] {taskinstance.py:2330} INFO - Executing <Task(PythonOperator): train_lasso> on 2025-06-18 18:59:49.630931+00:00
[2025-06-18T19:00:16.248+0000] {standard_task_runner.py:63} INFO - Started process 8933 to run task
[2025-06-18T19:00:16.255+0000] {standard_task_runner.py:90} INFO - Running: ['***', 'tasks', 'run', 'kse100_forecasting', 'train_lasso', 'manual__2025-06-18T18:59:49.630931+00:00', '--job-id', '1042', '--raw', '--subdir', 'DAGS_FOLDER/kse100_forecasting_dag.py', '--cfg-path', '/tmp/tmpxpa8pbw8']
[2025-06-18T19:00:16.262+0000] {standard_task_runner.py:91} INFO - Job 1042: Subtask train_lasso
[2025-06-18T19:00:16.364+0000] {task_command.py:426} INFO - Running <TaskInstance: kse100_forecasting.train_lasso manual__2025-06-18T18:59:49.630931+00:00 [running]> on host 57c57e92cb28
[2025-06-18T19:00:16.598+0000] {taskinstance.py:2648} INFO - Exporting env vars: AIRFLOW_CTX_DAG_OWNER='***' AIRFLOW_CTX_DAG_ID='kse100_forecasting' AIRFLOW_CTX_TASK_ID='train_lasso' AIRFLOW_CTX_EXECUTION_DATE='2025-06-18T18:59:49.630931+00:00' AIRFLOW_CTX_TRY_NUMBER='1' AIRFLOW_CTX_DAG_RUN_ID='manual__2025-06-18T18:59:49.630931+00:00'
[2025-06-18T19:00:16.599+0000] {taskinstance.py:430} INFO - ::endgroup::
[2025-06-18T19:00:17.020+0000] {logging_mixin.py:188} INFO - Lasso: R2=0.6988, MSE=7599593.9128, MAE=2125.0455
[2025-06-18T19:00:17.055+0000] {logging_mixin.py:188} INFO - Error predicting on full dataset (Lasso): [Errno 2] No such file or directory: '/opt/***/data/transformed_data.csv'
[2025-06-18T19:00:17.056+0000] {python.py:237} INFO - Done. Returned value was: ('/opt/***/dataKse/models/kse_lasso_model.pkl', '/opt/***/dataKse/models/kse_lasso_metrics.csv')
[2025-06-18T19:00:17.057+0000] {taskinstance.py:441} INFO - ::group::Post task execution logs
[2025-06-18T19:00:17.112+0000] {taskinstance.py:1206} INFO - Marking task as SUCCESS. dag_id=kse100_forecasting, task_id=train_lasso, run_id=manual__2025-06-18T18:59:49.630931+00:00, execution_date=20250618T185949, start_date=20250618T190016, end_date=20250618T190017
[2025-06-18T19:00:17.203+0000] {local_task_job_runner.py:240} INFO - Task exited with return code 0
[2025-06-18T19:00:17.219+0000] {taskinstance.py:3498} INFO - 0 downstream tasks scheduled from follow-on schedule check
[2025-06-18T19:00:17.221+0000] {local_task_job_runner.py:222} INFO - ::endgroup::
