[2025-06-14T15:30:20.337+0000] {local_task_job_runner.py:120} INFO - ::group::Pre task execution logs
[2025-06-14T15:30:20.453+0000] {taskinstance.py:2076} INFO - Dependencies all met for dep_context=non-requeueable deps ti=<TaskInstance: usdpkr_forecasting_modular.fetch_inflation scheduled__2025-05-01T00:00:00+00:00 [queued]>
[2025-06-14T15:30:20.512+0000] {taskinstance.py:2076} INFO - Dependencies all met for dep_context=requeueable deps ti=<TaskInstance: usdpkr_forecasting_modular.fetch_inflation scheduled__2025-05-01T00:00:00+00:00 [queued]>
[2025-06-14T15:30:20.513+0000] {taskinstance.py:2306} INFO - Starting attempt 1 of 2
[2025-06-14T15:30:20.546+0000] {taskinstance.py:2330} INFO - Executing <Task(PythonOperator): fetch_inflation> on 2025-05-01 00:00:00+00:00
[2025-06-14T15:30:20.580+0000] {standard_task_runner.py:63} INFO - Started process 366 to run task
[2025-06-14T15:30:20.592+0000] {standard_task_runner.py:90} INFO - Running: ['***', 'tasks', 'run', 'usdpkr_forecasting_modular', 'fetch_inflation', 'scheduled__2025-05-01T00:00:00+00:00', '--job-id', '183', '--raw', '--subdir', 'DAGS_FOLDER/usdpkr_forecasting_dag.py', '--cfg-path', '/tmp/tmpmhasjlz6']
[2025-06-14T15:30:20.609+0000] {standard_task_runner.py:91} INFO - Job 183: Subtask fetch_inflation
[2025-06-14T15:30:20.731+0000] {task_command.py:426} INFO - Running <TaskInstance: usdpkr_forecasting_modular.fetch_inflation scheduled__2025-05-01T00:00:00+00:00 [running]> on host 1ada37a5d2dc
[2025-06-14T15:30:20.937+0000] {taskinstance.py:2648} INFO - Exporting env vars: AIRFLOW_CTX_DAG_OWNER='***' AIRFLOW_CTX_DAG_ID='usdpkr_forecasting_modular' AIRFLOW_CTX_TASK_ID='fetch_inflation' AIRFLOW_CTX_EXECUTION_DATE='2025-05-01T00:00:00+00:00' AIRFLOW_CTX_TRY_NUMBER='1' AIRFLOW_CTX_DAG_RUN_ID='scheduled__2025-05-01T00:00:00+00:00'
[2025-06-14T15:30:20.938+0000] {taskinstance.py:430} INFO - ::endgroup::
[2025-06-14T15:30:20.962+0000] {logging_mixin.py:188} INFO - Fetching 'INFLATION_YOY' from IMF (ID: PCPI_IX)...
[2025-06-14T15:30:21.800+0000] {taskinstance.py:441} INFO - ::group::Post task execution logs
[2025-06-14T15:30:21.801+0000] {taskinstance.py:2905} ERROR - Task failed with exception
Traceback (most recent call last):
  File "/home/airflow/.local/lib/python3.12/site-packages/airflow/models/taskinstance.py", line 465, in _execute_task
    result = _execute_callable(context=context, **execute_callable_kwargs)
             ^^^^^^^^^^^^^^^^^^^^^^^^^^^^^^^^^^^^^^^^^^^^^^^^^^^^^^^^^^^^^
  File "/home/airflow/.local/lib/python3.12/site-packages/airflow/models/taskinstance.py", line 432, in _execute_callable
    return execute_callable(context=context, **execute_callable_kwargs)
           ^^^^^^^^^^^^^^^^^^^^^^^^^^^^^^^^^^^^^^^^^^^^^^^^^^^^^^^^^^^^
  File "/home/airflow/.local/lib/python3.12/site-packages/airflow/models/baseoperator.py", line 400, in wrapper
    return func(self, *args, **kwargs)
           ^^^^^^^^^^^^^^^^^^^^^^^^^^^
  File "/home/airflow/.local/lib/python3.12/site-packages/airflow/operators/python.py", line 235, in execute
    return_value = self.execute_callable()
                   ^^^^^^^^^^^^^^^^^^^^^^^
  File "/home/airflow/.local/lib/python3.12/site-packages/airflow/operators/python.py", line 252, in execute_callable
    return self.python_callable(*self.op_args, **self.op_kwargs)
           ^^^^^^^^^^^^^^^^^^^^^^^^^^^^^^^^^^^^^^^^^^^^^^^^^^^^^
  File "/opt/airflow/dags/inflation_modules/ingest.py", line 106, in fetch_imf_data
    df.to_csv(out_path, date_format='%Y-%m-%d')
  File "/home/airflow/.local/lib/python3.12/site-packages/pandas/core/generic.py", line 3902, in to_csv
    return DataFrameRenderer(formatter).to_csv(
           ^^^^^^^^^^^^^^^^^^^^^^^^^^^^^^^^^^^^
  File "/home/airflow/.local/lib/python3.12/site-packages/pandas/io/formats/format.py", line 1152, in to_csv
    csv_formatter.save()
  File "/home/airflow/.local/lib/python3.12/site-packages/pandas/io/formats/csvs.py", line 247, in save
    with get_handle(
         ^^^^^^^^^^^
  File "/home/airflow/.local/lib/python3.12/site-packages/pandas/io/common.py", line 739, in get_handle
    check_parent_directory(str(handle))
  File "/home/airflow/.local/lib/python3.12/site-packages/pandas/io/common.py", line 604, in check_parent_directory
    raise OSError(rf"Cannot save file into a non-existent directory: '{parent}'")
OSError: Cannot save file into a non-existent directory: '/opt/***/data/raw'
[2025-06-14T15:30:21.817+0000] {taskinstance.py:1206} INFO - Marking task as UP_FOR_RETRY. dag_id=usdpkr_forecasting_modular, task_id=fetch_inflation, run_id=scheduled__2025-05-01T00:00:00+00:00, execution_date=20250501T000000, start_date=20250614T153020, end_date=20250614T153021
[2025-06-14T15:30:21.827+0000] {standard_task_runner.py:110} ERROR - Failed to execute job 183 for task fetch_inflation (Cannot save file into a non-existent directory: '/opt/***/data/raw'; 366)
[2025-06-14T15:30:21.843+0000] {local_task_job_runner.py:240} INFO - Task exited with return code 1
[2025-06-14T15:30:21.869+0000] {taskinstance.py:3498} INFO - 0 downstream tasks scheduled from follow-on schedule check
[2025-06-14T15:30:21.871+0000] {local_task_job_runner.py:222} INFO - ::endgroup::
