[2025-06-14T16:55:32.834+0000] {local_task_job_runner.py:120} INFO - ::group::Pre task execution logs
[2025-06-14T16:55:32.861+0000] {taskinstance.py:2076} INFO - Dependencies all met for dep_context=non-requeueable deps ti=<TaskInstance: usdpkr_forecasting_modular.feature_engineering manual__2025-06-14T16:55:18.385585+00:00 [queued]>
[2025-06-14T16:55:32.870+0000] {taskinstance.py:2076} INFO - Dependencies all met for dep_context=requeueable deps ti=<TaskInstance: usdpkr_forecasting_modular.feature_engineering manual__2025-06-14T16:55:18.385585+00:00 [queued]>
[2025-06-14T16:55:32.870+0000] {taskinstance.py:2306} INFO - Starting attempt 1 of 3
[2025-06-14T16:55:32.885+0000] {taskinstance.py:2330} INFO - Executing <Task(PythonOperator): feature_engineering> on 2025-06-14 16:55:18.385585+00:00
[2025-06-14T16:55:32.892+0000] {standard_task_runner.py:63} INFO - Started process 351 to run task
[2025-06-14T16:55:32.895+0000] {standard_task_runner.py:90} INFO - Running: ['***', 'tasks', 'run', 'usdpkr_forecasting_modular', 'feature_engineering', 'manual__2025-06-14T16:55:18.385585+00:00', '--job-id', '331', '--raw', '--subdir', 'DAGS_FOLDER/usdpkr_forecasting_dag.py', '--cfg-path', '/tmp/tmp83rrwzgn']
[2025-06-14T16:55:32.897+0000] {standard_task_runner.py:91} INFO - Job 331: Subtask feature_engineering
[2025-06-14T16:55:32.938+0000] {task_command.py:426} INFO - Running <TaskInstance: usdpkr_forecasting_modular.feature_engineering manual__2025-06-14T16:55:18.385585+00:00 [running]> on host 1ada37a5d2dc
[2025-06-14T16:55:33.076+0000] {taskinstance.py:2648} INFO - Exporting env vars: AIRFLOW_CTX_DAG_OWNER='***' AIRFLOW_CTX_DAG_ID='usdpkr_forecasting_modular' AIRFLOW_CTX_TASK_ID='feature_engineering' AIRFLOW_CTX_EXECUTION_DATE='2025-06-14T16:55:18.385585+00:00' AIRFLOW_CTX_TRY_NUMBER='1' AIRFLOW_CTX_DAG_RUN_ID='manual__2025-06-14T16:55:18.385585+00:00'
[2025-06-14T16:55:33.077+0000] {taskinstance.py:430} INFO - ::endgroup::
[2025-06-14T16:55:33.089+0000] {transform.py:340} ERROR - Error in engineer_features: 'str' object has no attribute 'shape'
[2025-06-14T16:55:33.090+0000] {transform.py:341} ERROR - Error type: <class 'AttributeError'>
[2025-06-14T16:55:33.091+0000] {taskinstance.py:441} INFO - ::group::Post task execution logs
[2025-06-14T16:55:33.091+0000] {taskinstance.py:2905} ERROR - Task failed with exception
Traceback (most recent call last):
  File "/opt/airflow/dags/inflation_modules/transform.py", line 271, in engineer_features
    logging.info(f"Starting feature engineering. Input DataFrame shape: {df.shape}")
                                                                         ^^^^^^^^
AttributeError: 'str' object has no attribute 'shape'

During handling of the above exception, another exception occurred:

Traceback (most recent call last):
  File "/home/airflow/.local/lib/python3.12/site-packages/airflow/models/taskinstance.py", line 465, in _execute_task
    result = _execute_callable(context=context, **execute_callable_kwargs)
             ^^^^^^^^^^^^^^^^^^^^^^^^^^^^^^^^^^^^^^^^^^^^^^^^^^^^^^^^^^^^^
  File "/home/airflow/.local/lib/python3.12/site-packages/airflow/models/taskinstance.py", line 432, in _execute_callable
    return execute_callable(context=context, **execute_callable_kwargs)
           ^^^^^^^^^^^^^^^^^^^^^^^^^^^^^^^^^^^^^^^^^^^^^^^^^^^^^^^^^^^^
  File "/home/airflow/.local/lib/python3.12/site-packages/airflow/models/baseoperator.py", line 400, in wrapper
    return func(self, *args, **kwargs)
           ^^^^^^^^^^^^^^^^^^^^^^^^^^^
  File "/home/airflow/.local/lib/python3.12/site-packages/airflow/operators/python.py", line 235, in execute
    return_value = self.execute_callable()
                   ^^^^^^^^^^^^^^^^^^^^^^^
  File "/home/airflow/.local/lib/python3.12/site-packages/airflow/operators/python.py", line 252, in execute_callable
    return self.python_callable(*self.op_args, **self.op_kwargs)
           ^^^^^^^^^^^^^^^^^^^^^^^^^^^^^^^^^^^^^^^^^^^^^^^^^^^^^
  File "/opt/airflow/dags/inflation_modules/transform.py", line 342, in engineer_features
    logging.error(f"DataFrame info at time of error:\n{df.info()}")
                                                       ^^^^^^^
AttributeError: 'str' object has no attribute 'info'
[2025-06-14T16:55:33.107+0000] {taskinstance.py:1206} INFO - Marking task as UP_FOR_RETRY. dag_id=usdpkr_forecasting_modular, task_id=feature_engineering, run_id=manual__2025-06-14T16:55:18.385585+00:00, execution_date=20250614T165518, start_date=20250614T165532, end_date=20250614T165533
[2025-06-14T16:55:33.116+0000] {standard_task_runner.py:110} ERROR - Failed to execute job 331 for task feature_engineering ('str' object has no attribute 'info'; 351)
[2025-06-14T16:55:33.148+0000] {local_task_job_runner.py:240} INFO - Task exited with return code 1
[2025-06-14T16:55:33.169+0000] {taskinstance.py:3498} INFO - 0 downstream tasks scheduled from follow-on schedule check
[2025-06-14T16:55:33.172+0000] {local_task_job_runner.py:222} INFO - ::endgroup::
