[2025-06-18T10:38:15.528+0000] {local_task_job_runner.py:120} INFO - ::group::Pre task execution logs
[2025-06-18T10:38:15.558+0000] {taskinstance.py:2076} INFO - Dependencies all met for dep_context=non-requeueable deps ti=<TaskInstance: usdpkr_forecasting_modular.train_lasso manual__2025-06-14T17:31:51.405170+00:00 [queued]>
[2025-06-18T10:38:15.567+0000] {taskinstance.py:2076} INFO - Dependencies all met for dep_context=requeueable deps ti=<TaskInstance: usdpkr_forecasting_modular.train_lasso manual__2025-06-14T17:31:51.405170+00:00 [queued]>
[2025-06-18T10:38:15.567+0000] {taskinstance.py:2306} INFO - Starting attempt 1 of 3
[2025-06-18T10:38:15.581+0000] {taskinstance.py:2330} INFO - Executing <Task(PythonOperator): train_lasso> on 2025-06-14 17:31:51.405170+00:00
[2025-06-18T10:38:15.587+0000] {standard_task_runner.py:63} INFO - Started process 257 to run task
[2025-06-18T10:38:15.590+0000] {standard_task_runner.py:90} INFO - Running: ['***', 'tasks', 'run', 'usdpkr_forecasting_modular', 'train_lasso', 'manual__2025-06-14T17:31:51.405170+00:00', '--job-id', '503', '--raw', '--subdir', 'DAGS_FOLDER/usdpkr_forecasting_dag.py', '--cfg-path', '/tmp/tmpa5d5wv5y']
[2025-06-18T10:38:15.593+0000] {standard_task_runner.py:91} INFO - Job 503: Subtask train_lasso
[2025-06-18T10:38:15.632+0000] {task_command.py:426} INFO - Running <TaskInstance: usdpkr_forecasting_modular.train_lasso manual__2025-06-14T17:31:51.405170+00:00 [running]> on host 9c4806d77c92
[2025-06-18T10:38:15.736+0000] {taskinstance.py:2648} INFO - Exporting env vars: AIRFLOW_CTX_DAG_OWNER='***' AIRFLOW_CTX_DAG_ID='usdpkr_forecasting_modular' AIRFLOW_CTX_TASK_ID='train_lasso' AIRFLOW_CTX_EXECUTION_DATE='2025-06-14T17:31:51.405170+00:00' AIRFLOW_CTX_TRY_NUMBER='1' AIRFLOW_CTX_DAG_RUN_ID='manual__2025-06-14T17:31:51.405170+00:00'
[2025-06-18T10:38:15.755+0000] {taskinstance.py:430} INFO - ::endgroup::
[2025-06-18T10:38:15.785+0000] {model_steps.py:809} ERROR - Error in train_lasso_model: Found array with 0 sample(s) (shape=(0, 45)) while a minimum of 1 is required by LassoCV.
[2025-06-18T10:38:15.785+0000] {taskinstance.py:441} INFO - ::group::Post task execution logs
[2025-06-18T10:38:15.786+0000] {taskinstance.py:2905} ERROR - Task failed with exception
Traceback (most recent call last):
  File "/home/airflow/.local/lib/python3.12/site-packages/airflow/models/taskinstance.py", line 465, in _execute_task
    result = _execute_callable(context=context, **execute_callable_kwargs)
             ^^^^^^^^^^^^^^^^^^^^^^^^^^^^^^^^^^^^^^^^^^^^^^^^^^^^^^^^^^^^^
  File "/home/airflow/.local/lib/python3.12/site-packages/airflow/models/taskinstance.py", line 432, in _execute_callable
    return execute_callable(context=context, **execute_callable_kwargs)
           ^^^^^^^^^^^^^^^^^^^^^^^^^^^^^^^^^^^^^^^^^^^^^^^^^^^^^^^^^^^^
  File "/home/airflow/.local/lib/python3.12/site-packages/airflow/models/baseoperator.py", line 400, in wrapper
    return func(self, *args, **kwargs)
           ^^^^^^^^^^^^^^^^^^^^^^^^^^^
  File "/home/airflow/.local/lib/python3.12/site-packages/airflow/operators/python.py", line 235, in execute
    return_value = self.execute_callable()
                   ^^^^^^^^^^^^^^^^^^^^^^^
  File "/home/airflow/.local/lib/python3.12/site-packages/airflow/operators/python.py", line 252, in execute_callable
    return self.python_callable(*self.op_args, **self.op_kwargs)
           ^^^^^^^^^^^^^^^^^^^^^^^^^^^^^^^^^^^^^^^^^^^^^^^^^^^^^
  File "/opt/airflow/dags/inflation_modules/model_steps.py", line 800, in train_lasso_model
    model.fit(X_train, y_train)
  File "/home/airflow/.local/lib/python3.12/site-packages/sklearn/linear_model/_coordinate_descent.py", line 2182, in fit
    return super().fit(X, y, sample_weight=sample_weight, **params)
           ^^^^^^^^^^^^^^^^^^^^^^^^^^^^^^^^^^^^^^^^^^^^^^^^^^^^^^^^
  File "/home/airflow/.local/lib/python3.12/site-packages/sklearn/base.py", line 1363, in wrapper
    return fit_method(estimator, *args, **kwargs)
           ^^^^^^^^^^^^^^^^^^^^^^^^^^^^^^^^^^^^^^
  File "/home/airflow/.local/lib/python3.12/site-packages/sklearn/linear_model/_coordinate_descent.py", line 1693, in fit
    X, y = validate_data(
           ^^^^^^^^^^^^^^
  File "/home/airflow/.local/lib/python3.12/site-packages/sklearn/utils/validation.py", line 2966, in validate_data
    X = check_array(X, input_name="X", **check_X_params)
        ^^^^^^^^^^^^^^^^^^^^^^^^^^^^^^^^^^^^^^^^^^^^^^^^
  File "/home/airflow/.local/lib/python3.12/site-packages/sklearn/utils/validation.py", line 1128, in check_array
    raise ValueError(
ValueError: Found array with 0 sample(s) (shape=(0, 45)) while a minimum of 1 is required by LassoCV.
[2025-06-18T10:38:15.799+0000] {taskinstance.py:1206} INFO - Marking task as UP_FOR_RETRY. dag_id=usdpkr_forecasting_modular, task_id=train_lasso, run_id=manual__2025-06-14T17:31:51.405170+00:00, execution_date=20250614T173151, start_date=20250618T103815, end_date=20250618T103815
[2025-06-18T10:38:16.220+0000] {standard_task_runner.py:110} ERROR - Failed to execute job 503 for task train_lasso (Found array with 0 sample(s) (shape=(0, 45)) while a minimum of 1 is required by LassoCV.; 257)
[2025-06-18T10:38:16.244+0000] {local_task_job_runner.py:240} INFO - Task exited with return code 1
[2025-06-18T10:38:16.265+0000] {taskinstance.py:3498} INFO - 0 downstream tasks scheduled from follow-on schedule check
[2025-06-18T10:38:16.268+0000] {local_task_job_runner.py:222} INFO - ::endgroup::
