[2025-06-14T15:35:23.224+0000] {local_task_job_runner.py:120} INFO - ::group::Pre task execution logs
[2025-06-14T15:35:23.326+0000] {taskinstance.py:2076} INFO - Dependencies all met for dep_context=non-requeueable deps ti=<TaskInstance: usdpkr_forecasting_modular.fetch_m2 scheduled__2025-05-01T00:00:00+00:00 [queued]>
[2025-06-14T15:35:23.351+0000] {taskinstance.py:2076} INFO - Dependencies all met for dep_context=requeueable deps ti=<TaskInstance: usdpkr_forecasting_modular.fetch_m2 scheduled__2025-05-01T00:00:00+00:00 [queued]>
[2025-06-14T15:35:23.352+0000] {taskinstance.py:2306} INFO - Starting attempt 2 of 2
[2025-06-14T15:35:23.385+0000] {taskinstance.py:2330} INFO - Executing <Task(PythonOperator): fetch_m2> on 2025-05-01 00:00:00+00:00
[2025-06-14T15:35:23.397+0000] {standard_task_runner.py:63} INFO - Started process 621 to run task
[2025-06-14T15:35:23.414+0000] {standard_task_runner.py:90} INFO - Running: ['***', 'tasks', 'run', 'usdpkr_forecasting_modular', 'fetch_m2', 'scheduled__2025-05-01T00:00:00+00:00', '--job-id', '192', '--raw', '--subdir', 'DAGS_FOLDER/usdpkr_forecasting_dag.py', '--cfg-path', '/tmp/tmp8c62o_sd']
[2025-06-14T15:35:23.423+0000] {standard_task_runner.py:91} INFO - Job 192: Subtask fetch_m2
[2025-06-14T15:35:23.556+0000] {task_command.py:426} INFO - Running <TaskInstance: usdpkr_forecasting_modular.fetch_m2 scheduled__2025-05-01T00:00:00+00:00 [running]> on host 1ada37a5d2dc
[2025-06-14T15:35:23.740+0000] {taskinstance.py:2648} INFO - Exporting env vars: AIRFLOW_CTX_DAG_OWNER='***' AIRFLOW_CTX_DAG_ID='usdpkr_forecasting_modular' AIRFLOW_CTX_TASK_ID='fetch_m2' AIRFLOW_CTX_EXECUTION_DATE='2025-05-01T00:00:00+00:00' AIRFLOW_CTX_TRY_NUMBER='2' AIRFLOW_CTX_DAG_RUN_ID='scheduled__2025-05-01T00:00:00+00:00'
[2025-06-14T15:35:23.752+0000] {taskinstance.py:430} INFO - ::endgroup::
[2025-06-14T15:35:23.793+0000] {ingest.py:193} INFO - Generating placeholder data for SBP series: M2...
[2025-06-14T15:35:23.808+0000] {ingest.py:220} ERROR - Error generating placeholder data for M2: Invalid frequency: ME
[2025-06-14T15:35:23.808+0000] {taskinstance.py:441} INFO - ::group::Post task execution logs
[2025-06-14T15:35:23.809+0000] {taskinstance.py:2905} ERROR - Task failed with exception
Traceback (most recent call last):
  File "offsets.pyx", line 4447, in pandas._libs.tslibs.offsets._get_offset
KeyError: 'ME'

The above exception was the direct cause of the following exception:

Traceback (most recent call last):
  File "offsets.pyx", line 4549, in pandas._libs.tslibs.offsets.to_offset
  File "offsets.pyx", line 4453, in pandas._libs.tslibs.offsets._get_offset
ValueError: Invalid frequency: ME

The above exception was the direct cause of the following exception:

Traceback (most recent call last):
  File "/home/airflow/.local/lib/python3.12/site-packages/airflow/models/taskinstance.py", line 465, in _execute_task
    result = _execute_callable(context=context, **execute_callable_kwargs)
             ^^^^^^^^^^^^^^^^^^^^^^^^^^^^^^^^^^^^^^^^^^^^^^^^^^^^^^^^^^^^^
  File "/home/airflow/.local/lib/python3.12/site-packages/airflow/models/taskinstance.py", line 432, in _execute_callable
    return execute_callable(context=context, **execute_callable_kwargs)
           ^^^^^^^^^^^^^^^^^^^^^^^^^^^^^^^^^^^^^^^^^^^^^^^^^^^^^^^^^^^^
  File "/home/airflow/.local/lib/python3.12/site-packages/airflow/models/baseoperator.py", line 400, in wrapper
    return func(self, *args, **kwargs)
           ^^^^^^^^^^^^^^^^^^^^^^^^^^^
  File "/home/airflow/.local/lib/python3.12/site-packages/airflow/operators/python.py", line 235, in execute
    return_value = self.execute_callable()
                   ^^^^^^^^^^^^^^^^^^^^^^^
  File "/home/airflow/.local/lib/python3.12/site-packages/airflow/operators/python.py", line 252, in execute_callable
    return self.python_callable(*self.op_args, **self.op_kwargs)
           ^^^^^^^^^^^^^^^^^^^^^^^^^^^^^^^^^^^^^^^^^^^^^^^^^^^^^
  File "/opt/airflow/dags/inflation_modules/ingest.py", line 196, in fetch_sbp_placeholder
    date_range = pd.date_range(start=start_date, end=end_date, freq='ME')
                 ^^^^^^^^^^^^^^^^^^^^^^^^^^^^^^^^^^^^^^^^^^^^^^^^^^^^^^^^
  File "/home/airflow/.local/lib/python3.12/site-packages/pandas/core/indexes/datetimes.py", line 1009, in date_range
    dtarr = DatetimeArray._generate_range(
            ^^^^^^^^^^^^^^^^^^^^^^^^^^^^^^
  File "/home/airflow/.local/lib/python3.12/site-packages/pandas/core/arrays/datetimes.py", line 404, in _generate_range
    freq = to_offset(freq)
           ^^^^^^^^^^^^^^^
  File "offsets.pyx", line 4460, in pandas._libs.tslibs.offsets.to_offset
  File "offsets.pyx", line 4557, in pandas._libs.tslibs.offsets.to_offset
ValueError: Invalid frequency: ME
[2025-06-14T15:35:23.823+0000] {taskinstance.py:1206} INFO - Marking task as FAILED. dag_id=usdpkr_forecasting_modular, task_id=fetch_m2, run_id=scheduled__2025-05-01T00:00:00+00:00, execution_date=20250501T000000, start_date=20250614T153523, end_date=20250614T153523
[2025-06-14T15:35:23.859+0000] {standard_task_runner.py:110} ERROR - Failed to execute job 192 for task fetch_m2 (Invalid frequency: ME; 621)
[2025-06-14T15:35:23.881+0000] {local_task_job_runner.py:240} INFO - Task exited with return code 1
[2025-06-14T15:35:23.945+0000] {taskinstance.py:3498} INFO - 0 downstream tasks scheduled from follow-on schedule check
[2025-06-14T15:35:23.965+0000] {local_task_job_runner.py:222} INFO - ::endgroup::
